Workbook

Sheet 읽어보기
A1: 원료 마스터 — 원료 하나를 끝까지 파서 원하는 제형을 만든다
A2: 제품개발_마스터의 '원료'(보유)·'원료 도감'을 깊게 판 학습 워크북. 재생성: uv run python scripts/ingredient_master.py (내 기록 칸은 보존).
A4: ■ 하루 1원료 루프 (15분)
A5: ① 카드 읽기 (5분) | B5: '원료 카드'에서 한 행을 왼쪽→오른쪽으로. 정체→감각→처방→사업→규제→판단 순서.
A6: ② 손 테스트 (5분) | B6: '손 테스트 과제' 열 그대로. 보유 원료는 지금 바로 가능 — 문서보다 손이 먼저.
A7: ③ 기록 (2분) | B7: 노란 칸: 손테스트 ○ · 내 관찰 메모(내 말로 한 줄) · 숙련도 드롭다운.
A8: ④ 비교 (3분) | B8: '비교 매트릭스'에서 같은 역할 원료와 점수 비교 → 내 손 결과와 다르면 점수를 고쳐 쓴다.
A10: ■ 시트 안내
A11: 진도판 | B11: 숙련도·손테스트 자동 집계. 목표: 보유 원료 마스터율 100%.
A12: 원료 카드 | B12: 247종 × 29개 항목. 역할 순서(용제→보습→점증→유화→오일→경화→실리콘→활성→…→향)로 정렬, 같은 역할 안에선 보유 원료가 위. '출처' 열: 기본(85·보유+핵심 비교) / 도감 기능성(58) / 허브누리(104·레시피 다빈도 단일 원료). ▼필터로 역할·보유·출처 탐색.
A13: 비교 매트릭스 | B13: 11개 그룹을 1~5점으로: 보습제 · 오일·에스터 · 왁스·경화(밤·립) · 점증제 · 유화제 · 실리콘·감촉 · 계면활성제(세정) · 방부 시스템 · 각질·산 · 미백·톤(고시=식약처 기능성 성분) · 에센셜오일(향).
A14: 제형 설계 | B14: 21개 제형(스킨케어·세정·헤어·밤·배스) → 뼈대·수상/유상%·원료 조합·감촉 레버·실패 원인·지금 가능 여부.
A15: 감촉 레버 | B15: 28개 '원하는 변화' → 올릴 것·내릴 것·바꿀 것·원리·확인 실험.
A16: 블렌드 해부 | B16: 허브누리 상품명·블렌드 원료 26종 → 추정 주성분·연결 카드·직접 만들면·살 때 받을 자료·광고 주의. 판매처/OEM 질문 목록으로 사용.
A17: 다음 공부 | B17: 도감(기능성 + 허브누리 2회↑) 중 아직 카드 없는 단일 원료 후보(자동). 블렌드는 '블렌드 해부'로, 완제 베이스·방향제는 제외.
A19: ■ 열 읽는 법 (핵심만)
A20: 기원 | B20: 식물·광물·발효·합성·석유·동물. '천연 유래'라도 가공(에스터화·수소화·에톡실화)을 거치면 성질이 바뀐다.
A21: 추출·제조·가공 | B21: 압착·증류·발효·에스터화·수소화·정제(탈색/탈취) — 같은 원료도 가공에 따라 색·냄새·안정성이 달라진다(골든 vs 정제 호호바).
A22: 투입 상·온도 | B22: A=수상(가열) · B=유상(가열·유화) · 냉각상(<40℃, 열에 약한 활성·방부) · pH=마지막 조정.
A23: 발림성 vs 사용감 | B23: 발림성=펴 바를 때 얼마나 잘 퍼지나(물리). 사용감=바르고 난 피부 느낌(끈적·보송·촉촉).
A24: 구하기 | B24: ★5=허브누리·천연사랑 등 소분몰 상시 / ★1=원료사·대리점 MOQ 필요.
A25: 사용제한·식약처 고시 | B25: ★ 표시 = 사용한도/기능성 고시 해당. 시험·판매 둘 다 직결 — 제품개발_마스터 '사용제한원료' 시트와 연결해서 볼 것.
A27: ■ 공부 우선순위
A28: 1단계 | B28: 보유(✓) 원료 29종 — 이미 손에 있다. 손 테스트로 숙련도 2 만들기.
A29: 2단계 | B29: 보유 원료의 '비교 원료' 열에 나온 것 — 왜 내가 그걸 안 골랐는지 설명할 수 있으면 마스터.
A30: 3단계 | B30: 제형 설계에서 '✗/구매 시' 제형을 열어주는 원료(카보머 입고·칸데릴라·HEC 등).
A31: 4단계 | B31: 허브누리 카드(꽃수·식물 오일·추출물·에센셜오일) — 레시피에서 자주 보는 원료를 '고시·알레르기·산패' 관점으로 다시 읽기.
A32: 허브누리 브랜드 원료 | B32: '올리브리퀴드·올리왁스LC·천연 보존제'처럼 판매처 상품명인 원료는 INCI 칸에 (예)·'TDS 확인'으로 표시 — 구매 시 전성분으로 확정.
A34: ⚠ 주의 | B34: 가격=2026 소량 소매 추정(직접 고쳐 쓰기). %·고시 수치는 교육용 정리 — 제조·판매·수출 전 식약처 최신 고시, 공급사 TDS/CoA, 수출국 규정(EU·중국 등) 재확인. 화장품은 '치료·항염·살균' 등 의약품 오인 표방 금지.

Sheet 진도판
A1: 진도판 — 원료를 '읽은 것'에서 '처방에 쓴 것'까지
A2: 자동 집계(수식). '원료 카드'의 노란 칸(손테스트·숙련도)을 채우면 여기 숫자가 움직인다. 목표: 보유 원료 전부 '2 만져봄' 이상 → 비교 원료로 확장.
A4: 항목 | B4: 값 | D4: 숙련도 | E4: 원료 수 | F4: 비율
A5: 전체 원료 카드 | B5: =COUNTA('원료 카드'!$B$5:$B$251) | D5: 0 모름 | E5: =COUNTIF('원료 카드'!$AG$5:$AG$251,"0*") | F5: =IFERROR(E5/$B$5,0)
A6: 보유(✓) 원료 | B6: =COUNTIF('원료 카드'!$D$5:$D$251,"✓") | D6: 1 읽음 | E6: =COUNTIF('원료 카드'!$AG$5:$AG$251,"1*") | F6: =IFERROR(E6/$B$5,0)
A7: 손 테스트 완료(○) | B7: =COUNTIF('원료 카드'!$AE$5:$AE$251,"○") | D7: 2 만져봄 | E7: =COUNTIF('원료 카드'!$AG$5:$AG$251,"2*") | F7: =IFERROR(E7/$B$5,0)
A8: 보유 중 '2 만져봄' 이상 | B8: =COUNTIFS('원료 카드'!$D$5:$D$251,"✓",'원료 카드'!$AG$5:$AG$251,"2*")+COUNTIFS('원료 카드'!$D$5:$D$251,"✓",'원료 카드'!$AG$5:$AG$251,"3*") | D8: 3 처방에 씀 | E8: =COUNTIF('원료 카드'!$AG$5:$AG$251,"3*") | F8: =IFERROR(E8/$B$5,0)
A9: 보유 원료 마스터율 | B9: =IFERROR(B8/B6,0) | D9: 미기록 | E9: =B5-SUM(E5:E8) | F9: =IFERROR(E9/$B$5,0)
A12: 역할 | B12: 카드 수 | D12: 보유 | E12: 만져봄↑ | F12: 손테스트○
A13: 용제 | B13: =COUNTIF('원료 카드'!$E$5:$E$251,A13) | D13: =COUNTIFS('원료 카드'!$E$5:$E$251,A13,'원료 카드'!$D$5:$D$251,"✓") | E13: =COUNTIFS('원료 카드'!$E$5:$E$251,A13,'원료 카드'!$AG$5:$AG$251,"2*")+COUNTIFS('원료 카드'!$E$5:$E$251,A13,'원료 카드'!$AG$5:$AG$251,"3*") | F13: =COUNTIFS('원료 카드'!$E$5:$E$251,A13,'원료 카드'!$AE$5:$AE$251,"○")
A14: 보습 | B14: =COUNTIF('원료 카드'!$E$5:$E$251,A14) | D14: =COUNTIFS('원료 카드'!$E$5:$E$251,A14,'원료 카드'!$D$5:$D$251,"✓") | E14: =COUNTIFS('원료 카드'!$E$5:$E$251,A14,'원료 카드'!$AG$5:$AG$251,"2*")+COUNTIFS('원료 카드'!$E$5:$E$251,A14,'원료 카드'!$AG$5:$AG$251,"3*") | F14: =COUNTIFS('원료 카드'!$E$5:$E$251,A14,'원료 카드'!$AE$5:$AE$251,"○")
A15: 점증 | B15: =COUNTIF('원료 카드'!$E$5:$E$251,A15) | D15: =COUNTIFS('원료 카드'!$E$5:$E$251,A15,'원료 카드'!$D$5:$D$251,"✓") | E15: =COUNTIFS('원료 카드'!$E$5:$E$251,A15,'원료 카드'!$AG$5:$AG$251,"2*")+COUNTIFS('원료 카드'!$E$5:$E$251,A15,'원료 카드'!$AG$5:$AG$251,"3*") | F15: =COUNTIFS('원료 카드'!$E$5:$E$251,A15,'원료 카드'!$AE$5:$AE$251,"○")
A16: 유화 | B16: =COUNTIF('원료 카드'!$E$5:$E$251,A16) | D16: =COUNTIFS('원료 카드'!$E$5:$E$251,A16,'원료 카드'!$D$5:$D$251,"✓") | E16: =COUNTIFS('원료 카드'!$E$5:$E$251,A16,'원료 카드'!$AG$5:$AG$251,"2*")+COUNTIFS('원료 카드'!$E$5:$E$251,A16,'원료 카드'!$AG$5:$AG$251,"3*") | F16: =COUNTIFS('원료 카드'!$E$5:$E$251,A16,'원료 카드'!$AE$5:$AE$251,"○")
A17: 에몰리언트 | B17: =COUNTIF('원료 카드'!$E$5:$E$251,A17) | D17: =COUNTIFS('원료 카드'!$E$5:$E$251,A17,'원료 카드'!$D$5:$D$251,"✓") | E17: =COUNTIFS('원료 카드'!$E$5:$E$251,A17,'원료 카드'!$AG$5:$AG$251,"2*")+COUNTIFS('원료 카드'!$E$5:$E$251,A17,'원료 카드'!$AG$5:$AG$251,"3*") | F17: =COUNTIFS('원료 카드'!$E$5:$E$251,A17,'원료 카드'!$AE$5:$AE$251,"○")
A18: 경화 | B18: =COUNTIF('원료 카드'!$E$5:$E$251,A18) | D18: =COUNTIFS('원료 카드'!$E$5:$E$251,A18,'원료 카드'!$D$5:$D$251,"✓") | E18: =COUNTIFS('원료 카드'!$E$5:$E$251,A18,'원료 카드'!$AG$5:$AG$251,"2*")+COUNTIFS('원료 카드'!$E$5:$E$251,A18,'원료 카드'!$AG$5:$AG$251,"3*") | F18: =COUNTIFS('원료 카드'!$E$5:$E$251,A18,'원료 카드'!$AE$5:$AE$251,"○")
A19: 감촉·실리콘 | B19: =COUNTIF('원료 카드'!$E$5:$E$251,A19) | D19: =COUNTIFS('원료 카드'!$E$5:$E$251,A19,'원료 카드'!$D$5:$D$251,"✓") | E19: =COUNTIFS('원료 카드'!$E$5:$E$251,A19,'원료 카드'!$AG$5:$AG$251,"2*")+COUNTIFS('원료 카드'!$E$5:$E$251,A19,'원료 카드'!$AG$5:$AG$251,"3*") | F19: =COUNTIFS('원료 카드'!$E$5:$E$251,A19,'원료 카드'!$AE$5:$AE$251,"○")
A20: 활성 | B20: =COUNTIF('원료 카드'!$E$5:$E$251,A20) | D20: =COUNTIFS('원료 카드'!$E$5:$E$251,A20,'원료 카드'!$D$5:$D$251,"✓") | E20: =COUNTIFS('원료 카드'!$E$5:$E$251,A20,'원료 카드'!$AG$5:$AG$251,"2*")+COUNTIFS('원료 카드'!$E$5:$E$251,A20,'원료 카드'!$AG$5:$AG$251,"3*") | F20: =COUNTIFS('원료 카드'!$E$5:$E$251,A20,'원료 카드'!$AE$5:$AE$251,"○")
A21: 항산화 | B21: =COUNTIF('원료 카드'!$E$5:$E$251,A21) | D21: =COUNTIFS('원료 카드'!$E$5:$E$251,A21,'원료 카드'!$D$5:$D$251,"✓") | E21: =COUNTIFS('원료 카드'!$E$5:$E$251,A21,'원료 카드'!$AG$5:$AG$251,"2*")+COUNTIFS('원료 카드'!$E$5:$E$251,A21,'원료 카드'!$AG$5:$AG$251,"3*") | F21: =COUNTIFS('원료 카드'!$E$5:$E$251,A21,'원료 카드'!$AE$5:$AE$251,"○")
A22: 방부 | B22: =COUNTIF('원료 카드'!$E$5:$E$251,A22) | D22: =COUNTIFS('원료 카드'!$E$5:$E$251,A22,'원료 카드'!$D$5:$D$251,"✓") | E22: =COUNTIFS('원료 카드'!$E$5:$E$251,A22,'원료 카드'!$AG$5:$AG$251,"2*")+COUNTIFS('원료 카드'!$E$5:$E$251,A22,'원료 카드'!$AG$5:$AG$251,"3*") | F22: =COUNTIFS('원료 카드'!$E$5:$E$251,A22,'원료 카드'!$AE$5:$AE$251,"○")
A23: pH조절 | B23: =COUNTIF('원료 카드'!$E$5:$E$251,A23) | D23: =COUNTIFS('원료 카드'!$E$5:$E$251,A23,'원료 카드'!$D$5:$D$251,"✓") | E23: =COUNTIFS('원료 카드'!$E$5:$E$251,A23,'원료 카드'!$AG$5:$AG$251,"2*")+COUNTIFS('원료 카드'!$E$5:$E$251,A23,'원료 카드'!$AG$5:$AG$251,"3*") | F23: =COUNTIFS('원료 카드'!$E$5:$E$251,A23,'원료 카드'!$AE$5:$AE$251,"○")
A24: 킬레이트 | B24: =COUNTIF('원료 카드'!$E$5:$E$251,A24) | D24: =COUNTIFS('원료 카드'!$E$5:$E$251,A24,'원료 카드'!$D$5:$D$251,"✓") | E24: =COUNTIFS('원료 카드'!$E$5:$E$251,A24,'원료 카드'!$AG$5:$AG$251,"2*")+COUNTIFS('원료 카드'!$E$5:$E$251,A24,'원료 카드'!$AG$5:$AG$251,"3*") | F24: =COUNTIFS('원료 카드'!$E$5:$E$251,A24,'원료 카드'!$AE$5:$AE$251,"○")
... A30: 향 | B30: =COUNTIF('원료 카드'!$E$5:$E$251,A30) | D30: =COUNTIFS('원료 카드'!$E$5:$E$251,A30,'원료 카드'!$D$5:$D$251,"✓") | E30: =COUNTIFS('원료 카드'!$E$5:$E$251,A30,'원료 카드'!$AG$5:$AG$251,"2*")+COUNTIFS('원료 카드'!$E$5:$E$251,A30,'원료 카드'!$AG$5:$AG$251,"3*") | F30: =COUNTIFS('원료 카드'!$E$5:$E$251,A30,'원료 카드'!$AE$5:$AE$251,"○")

Sheet 원료 카드
A1: 원료 카드 — 247종 심화 (보유 원료 전부 + 비교 핵심 원료)
A2: 1행=원료 1개. 왼쪽→오른쪽 순서가 곧 공부 순서: ①정체(기원·원재료·가공) ②감각(형태·색·냄새·사용감·발림성) ③처방(%·상·pH·궁합) ④사업(가격·구하기·보관) ⑤규제(고시·시험) ⑥판단(비교·고르는 기준) ⑦손 테스트. ┃ 노란 칸 3개(손테스트·내 관찰 메모·숙련도)만 내가 적는 칸 — 재생성해도 보존. ┃ 보유: ✓=있음, 주문=입고 대기, 필요=구매 필요, –=미보유(비교용). ┃ ⚠ 가격은 2026 소량 소매 추정, 고시 수치는 교육용 정리 — 판매 전 식약처 최신 고시·TDS 재확인.
B3: ① 정체 — 무엇이고 어디서 어떻게 오나 | K3: ② 감각 — 보고·맡고·발라보기 | S3: ③ 처방 — 얼마나·언제·무엇과 | V3: ④ 사업 — 가격·조달·보관 | Y3: ⑤ 규제·시험 | AA3: ⑥ 판단 · ⑦ 손 테스트 | AE3: ✍ 내 기록(입력)
A4: No | B4: 원료 | C4: INCI | D4: 보유 | E4: 역할(주) | F4: 보조 역할 | G4: 기원 | H4: 어디서 얻나(원재료) | I4: 추출·제조·가공 | J4: 화학 분류 | K4: 형태 | L4: 색 | M4: 냄새 | N4: 용해성 | O4: 투입 상·온도 | P4: 사용감 | Q4: 발림성 | R4: 마무리·잔여감 | S4: 전형 % | T4: pH·안정성 | U4: 궁합·주의(배합) | V4: 가격대(소량·추정) | W4: 구하기 | X4: 보관·유통 | Y4: 사용제한·식약처 고시 | Z4: 시험 포인트 | AA4: 비교 원료 | AB4: 고르는 기준(vs 비교) | AC4: 손 테스트 과제(5분) | AD4: 출처 | AE4: 손테스트 | AF4: 내 관찰 메모 | AG4: 숙련도
A5: 1 | B5: 정제수 | C5: Water | D5: ✓ | E5: 용제 | F5: 수상 베이스·용해 매체 | G5: 합성(정제) | H5: 상수·지하수 | I5: 이온교환·역삼투(RO)·UV 살균·0.2µm 필터 | J5: — | K5: 액상 | L5: 무색 투명 | M5: 무취 | N5: — | O5: A상, 70~80℃ 가열 | P5: 감각 없음 — 산뜻함의 바탕 | Q5: — | R5: 증발하며 시원함 | S5: 50~85% | T5: CO₂ 흡수로 pH 5.5~6.5 나올 수 있음 | U5: 미생물 오염 1순위. 개봉 후 빨리, 수돗물·생수 금지 | V5: ₩2,000~4,000/1L | W5: ★★★★★ | X5: 밀봉·서늘, 개봉 후 단기 | Y5: 제한 없음(원료규격: 미생물·중금속) | Z5: 수상 대표 원료, 맞춤형 조제 시 위생 관리 | AA5: 하이드로졸(로즈워터)·알로에즙 | AB5: 하이드로졸은 향·스토리 ↑ but 미생물↑·방부 부담↑ | AC5: pH 스트립으로 갓 딴 정제수 vs 하루 연 정제수 pH 비교 — 왜 산성 쪽으로 가나? | AD5: 기본
A6: 2 | B6: 로즈워터(하이드로졸) | C6: Rosa Damascena Flower Water | D6: – | E6: 용제 | F6: 향·스토리 수상 | G6: 식물 | H6: 다마스크 장미 꽃 | I6: 수증기 증류 시 정유와 함께 나오는 증류수 | J6: 꽃수(플로럴워터) | K6: 액상 | L6: 무색 | M6: 장미향(은은) | N6: 수용성 | O6: A상(정제수 대체) — 가열 시 향 손실 | P6: 산뜻 | Q6: — | R6: — | S6: 10~50% | T6: 미생물 취약 → 방부 필수 | U6: 정제수보다 오염 쉬움. 소량 구매·냉장 | V6: ₩10,000/250ml | W6: ★★★★★ | X6: 냉장 | Y6: 제한 없음 (향 성분 표시 고려) | Z6: — | AA6: 정제수·네롤리워터 | AB6: 향·스토리 원하면. 무향 민감 라인엔 X | AC6: 로즈워터 vs 정제수 토너 2개 — 향 지속 비교 | AD6: 기본
A7: 3 | B7: 네롤리워터 | C7: Citrus Aurantium Amara Flower Water | D7: – | E7: 용제 | F7: 향·스토리 수상 | G7: 식물 | H7: 비터오렌지 꽃 | I7: 수증기 증류(네롤리 정유 부산 증류수) | J7: 꽃수 | K7: 액상 | L7: 무색 | M7: 달콤 쌉쌀한 꽃향 | N7: 수용성 | O7: A상 대체(가열 시 향 손실 → 냉각상 권장) | P7: 산뜻 | Q7: — | R7: — | S7: 10~50% | T7: 미생물 취약 | U7: 정제수보다 오염 쉬움 → 방부 필수·냉장 | V7: ₩10,000/250ml | W7: ★★★★★ | X7: 냉장 | Y7: 제한 없음 (향 성분 표시 고려) | Z7: — | AA7: 로즈워터·라벤더워터 | AB7: 허브누리 2위 수상. 고급 플로럴 무드 | AC7: 네롤리워터 vs 로즈워터 향 맡고 기록 | AD7: 허브누리
A8: 4 | B8: 라벤더워터 | C8: Lavandula Angustifolia Flower Water | D8: – | E8: 용제 | F8: 향·진정 무드 | G8: 식물 | H8: 라벤더 꽃 | I8: 수증기 증류 | J8: 꽃수 | K8: 액상 | L8: 무색 | M8: 허브 꽃향 | N8: 수용성 | O8: 냉각상 권장 | P8: 산뜻 | Q8: — | R8: — | S8: 10~50% | T8: 미생물 취약 | U8: — | V8: ₩8,000/250ml | W8: ★★★★★ | X8: 냉장 | Y8: 제한 없음 | Z8: — | AA8: 캐모마일워터 | AB8: 무난한 진정 무드 수상 | AC8: — | AD8: 허브누리
A9: 5 | B9: 로먼캐모마일워터 | C9: Anthemis Nobilis Flower Water | D9: – | E9: 용제 | F9: 진정 무드 | G9: 식물 | H9: 로먼 캐모마일 꽃 | I9: 수증기 증류 | J9: 꽃수 | K9: 액상 | L9: 무색 | M9: 사과 같은 허브향 | N9: 수용성 | O9: 냉각상 권장 | P9: 산뜻 | Q9: — | R9: — | S9: 10~50% | T9: 미생물 취약 | U9: 국화과 알레르기 주의 | V9: ₩10,000/250ml | W9: ★★★★☆ | X9: 냉장 | Y9: 제한 없음 | Z9: — | AA9: 라벤더워터 | AB9: 예민 피부 무드 | AC9: — | AD9: 허브누리
A10: 6 | B10: 로즈마리워터 | C10: Rosmarinus Officinalis Leaf Water | D10: – | E10: 용제 | F10: 상쾌·두피 무드 | G10: 식물 | H10: 로즈마리 잎 | I10: 수증기 증류 | J10: 꽃수(잎수) | K10: 액상 | L10: 무색 | M10: 캠퍼성 허브향 | N10: 수용성 | O10: 냉각상 권장 | P10: 청량 | Q10: — | R10: — | S10: 10~60% | T10: 미생물 취약 | U10: — | V10: ₩8,000/250ml | W10: ★★★★☆ | X10: 냉장 | Y10: 제한 없음 | Z10: — | AA10: 티트리워터·편백워터 | AB10: 두피·지성 라인 수상 | AC10: — | AD10: 허브누리
A11: 7 | B11: 편백워터 | C11: Chamaecyparis Obtusa Water | D11: – | E11: 용제 | F11: 피톤치드 무드 | G11: 식물 | H11: 편백나무 잎·줄기 | I11: 수증기 증류 | J11: 목질 하이드로졸 | K11: 액상 | L11: 무색 | M11: 숲·나무향 | N11: 수용성 | O11: 냉각상 | P11: 산뜻 | Q11: — | R11: — | S11: 10~50% | T11: 미생물 취약 | U11: 국내산 스토리 | V11: ₩8,000/500ml | W11: ★★★★☆ | X11: 서늘 | Y11: 제한 없음 | Z11: — | AA11: 티트리워터 | AB11: K-로컬 숲 스토리 | AC11: — | AD11: 허브누리
A12: 8 | B12: 티트리워터 | C12: Melaleuca Alternifolia Leaf Water | D12: – | E12: 용제 | F12: 지성·트러블 무드 | G12: 식물 | H12: 티트리 잎 | I12: 수증기 증류 | J12: 잎수 | K12: 액상 | L12: 무색 | M12: 약용 허브향 | N12: 수용성 | O12: 냉각상 | P12: 청량 | Q12: — | R12: — | S12: 10~50% | T12: 미생물 취약 | U12: '여드름 치료' 표방 금지 | V12: ₩8,000/250ml | W12: ★★★★☆ | X12: 냉장 | Y12: 제한 없음 | Z12: — | AA12: 로즈마리워터·위치하젤워터 | AB12: 트러블 라인 무드 | AC12: — | AD12: 허브누리
A13: 9 | B13: 위치하젤워터 | C13: Hamamelis Virginiana Water | D13: – | E13: 용제 | F13: 수렴·모공 무드 | G13: 식물 | H13: 위치하젤 나무 잎·가지 | I13: 수증기 증류(일부 에탄올 함유 제품) | J13: 하이드로졸(탄닌) | K13: 액상 | L13: 무색 | M13: 약한 나무향 | N13: 수용성 | O13: 냉각상 | P13: 산뜻·약간 조임 | Q13: — | R13: — | S13: 10~50% | T13: 미생물 취약 | U13: 에탄올 함유 여부 전성분 확인(건조감) | V13: ₩10,000/250ml | W13: ★★★☆☆ | X13: 서늘 | Y13: 제한 없음 | Z13: — | AA13: 티트리워터 | AB13: 수렴 토너 무드 | AC13: — | AD13: 허브누리
A14: 10 | B14: 일랑일랑워터 | C14: Cananga Odorata Flower Water | D14: – | E14: 용제 | F14: 향·스토리 수상(이국적 플로럴) | G14: 식물 | H14: 일랑일랑 꽃 | I14: 수증기 증류(정유 증류 시 나오는 증류수) | J14: 꽃수 | K14: 액상 | L14: 무색 | M14: 진하고 달콤한 꽃향(EO보다 약함) | N14: 수용성 | O14: 냉각상 권장(가열 시 향 손실) | P14: 산뜻 | Q14: — | R14: — | S14: 10~50% (토너는 정제수 대체) | T14: 미생물 취약 | U14: 향이 강해 다른 꽃수와 블렌드하면 무난. 방부 필수 | V14: ₩10,000/250ml | W14: ★★★★☆ | X14: 냉장·차광 | Y14: 제한 없음 (향 성분 표시 고려) | Z14: — | AA14: 네롤리워터·로즈워터 | AB14: '피지 균형' 문구는 마케팅 — 실제론 향·무드 수상 | AC14: 일랑일랑워터 vs 네롤리워터 — 시향지에 묻혀 10분 뒤 남는 향 비교 | AD14: 허브누리
A15: 11 | B15: 레몬밤워터 | C15: Melissa Officinalis Leaf Water | D15: – | E15: 용제 | F15: 진정 무드·상쾌 수상 | G15: 식물 | H15: 레몬밤(멜리사) 잎 | I15: 수증기 증류 | J15: 잎수(하이드로졸) | K15: 액상 | L15: 무색 | M15: 레몬 같은 허브향(약함) | N15: 수용성 | O15: 냉각상 | P15: 산뜻·청량 | Q15: — | R15: — | S15: 10~50% | T15: 미생물 취약 | U15: 멜리사 EO는 매우 비싸고 위조 많음 → 워터로 스토리만 가져오는 경우 많음 | V15: ₩10,000/250ml | W15: ★★★☆☆ | X15: 냉장 | Y15: 제한 없음 | Z15: — | AA15: 라벤더워터·로먼캐모마일워터 | AB15: 레몬향 무드인데 시트러스 광독성 걱정 없음 | AC15: 레몬밤워터 vs 레몬EO 1방울 물 — 향 결이 어떻게 다른지 | AD15: 허브누리
A16: 12 | B16: 비타민 나무 워터 | C16: Hippophae Rhamnoides Fruit Water | D16: – | E16: 용제 | F16: 비타민 스토리 수상 | G16: 식물 | H16: 비타민나무(씨벅턴) 열매 | I16: 열매 증류(증류수) — 오일·과즙과 다른 부분 | J16: 과실 증류수 | K16: 액상 | L16: 무색~미황 | M16: 약한 새콤 과일취 | N16: 수용성 | O16: 냉각상 | P16: 산뜻 | Q16: — | R16: — | S16: 30~80% | T16: 미생물 취약 | U16: ★ 증류수엔 비타민C가 거의 안 넘어옴(비휘발성) → '비타민C 함유' 광고 근거 약함 | V16: ₩10,000/250ml | W16: ★★★☆☆ | X16: 냉장 | Y16: 제한 없음 | Z16: 원료 '스토리'와 실제 성분 구분 사례 | AA16: 씨벅턴오일(CO₂)·순수 비타민C | AB16: 씨벅턴의 진짜 성분은 오일(카로티노이드)에 있음 — 워터는 무드 | AC16: (공부) 씨벅턴오일 카드와 비교: 열매 하나에서 오일·워터·과즙이 각각 무엇을 담는지 적기 | AD16: 허브누리
... A251: 247 | B251: 주니퍼베리에센셜오일 | C251: Juniperus Communis Fruit Oil | D251: – | E251: 향 | F251: 상쾌한 우디·진(gin) 향 | G251: 식물 | H251: 주니퍼(노간주) 열매 | I251: 수증기 증류 | J251: 향료(α-피넨·미르센) | K251: 액상 | L251: 무색 | M251: 상쾌한 숲·진 향 | N251: 유용성 | O251: 냉각상 | P251: — | Q251: — | R251: — | S251: 0.5~1% | T251: ★ 산화 빠름 → 산화물은 감작성↑ (차광·소용량·토코페롤) | U251: '디톡스·노폐물 배출' 표현은 근거·광고 리스크 | V251: ₩12,000/10ml | W251: ★★★☆☆ | X251: 냉장·차광 | Y251: IFRA: 과산화물가 낮은 원료 사용 권장 | Z251: — | AA251: 편백에센셜오일·시더우드에센셜오일 | AB251: 남성·우디 라인 탑~미들 노트 | AC251: 주니퍼 vs 편백 시향 — 숲향 결 차이 적기 | AD251: 허브누리

Sheet 비교 매트릭스
A1: 비교 매트릭스 — 같은 역할끼리 1~5점으로
A2: 5 = 그 성질이 강함(끈적임·무게감도 5=많이 끈적/무거움). 가격 접근·구하기·다루기 쉬움은 5=저렴/쉬움. 점수는 일반적 경향의 상대 비교(내 손 테스트로 고쳐 써도 됨 — 파란 글씨=입력값). → '원하는 감촉'에 맞는 원료를 고를 때 행을 가로로 비교.
A4: ■ 보습제
A5: 원료 | B5: 보습력 | C5: 끈적임 | D5: 산뜻함 | E5: 방부 부스터 | F5: 가격 접근 | G5: 구하기
A6: 글리세린 | B6: 5 | C6: 4 | D6: 2 | E6: 1 | F6: 5 | G6: 5
A7: 프로판디올 | B7: 3 | C7: 2 | D7: 4 | E7: 3 | F7: 3 | G7: 4
A8: 부틸렌글라이콜(BG) | B8: 3 | C8: 2 | D8: 4 | E8: 2 | F8: 4 | G8: 4
A9: 펜틸렌글라이콜 | B9: 3 | C9: 1 | D9: 5 | E9: 4 | F9: 2 | G9: 3
A10: 베타인 | B10: 3 | C10: 1 | D10: 4 | E10: 1 | F10: 3 | G10: 4
A11: 다중 히알루론산 | B11: 4 | C11: 3 | D11: 3 | E11: 1 | F11: 1 | G11: 4
A12: 소듐PCA | B12: 4 | C12: 2 | D12: 4 | E12: 1 | F12: 3 | G12: 3
A13: 트레할로스 | B13: 3 | C13: 2 | D13: 4 | E13: 1 | F13: 3 | G13: 3
A14: 우레아 | B14: 4 | C14: 2 | D14: 4 | E14: 1 | F14: 5 | G14: 3
A15: 판테놀(B5) | B15: 3 | C15: 3 | D15: 3 | E15: 1 | F15: 3 | G15: 5
A16: 1,2-헥산다이올 | B16: 2 | C16: 1 | D16: 5 | E16: 4 | F16: 4 | G16: 5
A17: 폴리글루타믹애씨드(PGA) | B17: 4 | C17: 3 | D17: 3 | E17: 1 | F17: 1 | G17: 3
... A20: 허니(꿀) 추출물 | B20: 3 | C20: 4 | D20: 2 | E20: 1 | F20: 4 | G20: 4
A22: ■ 오일·에스터
A23: 원료 | B23: 발림성(퍼짐) | C23: 흡수 속도 | D23: 무게감 | E23: 윤기 | F23: 산화 안정성 | G23: 가격 접근
A24: 디카프릴릴카보네이트 | B24: 5 | C24: 5 | D24: 1 | E24: 1 | F24: 5 | G24: 2
A25: 코코-카프릴레이트/카프레이트 | B25: 5 | C25: 5 | D25: 1 | E25: 2 | F25: 5 | G25: 2
A26: 이소노닐이소노나노에이트 | B26: 5 | C26: 4 | D26: 1 | E26: 2 | F26: 5 | G26: 2
A27: 스쿠알란 | B27: 4 | C27: 4 | D27: 2 | E27: 2 | F27: 5 | G27: 2
A28: MCT오일 | B28: 4 | C28: 4 | D28: 2 | E28: 2 | F28: 5 | G28: 4
A29: C12-15 알킬벤조에이트 | B29: 4 | C29: 4 | D29: 2 | E29: 2 | F29: 5 | G29: 3
A30: 호호바오일 | B30: 3 | C30: 3 | D30: 3 | E30: 3 | F30: 5 | G30: 4
A31: 로즈힙오일 | B31: 3 | C31: 4 | D31: 2 | E31: 2 | F31: 1 | G31: 2
A32: 아르간오일 | B32: 3 | C32: 3 | D32: 3 | E32: 3 | F32: 3 | G32: 2
A33: 동백오일 | B33: 3 | C33: 2 | D33: 3 | E33: 4 | F33: 3 | G33: 2
A34: 해바라기씨유 | B34: 3 | C34: 2 | D34: 3 | E34: 3 | F34: 2 | G34: 5
A35: 미네랄오일/페트롤라툼 | B35: 2 | C35: 1 | D35: 5 | E35: 4 | F35: 5 | G35: 5
... A57: 코포아수버터 | B57: 2 | C57: 2 | D57: 4 | E57: 2 | F57: 4 | G57: 2
A59: ■ 왁스·경화(밤·립)
A60: 원료 | B60: 경도(같은 %) | C60: 끈적임 | D60: 광택 | E60: 녹는점(5=높음) | F60: 비건 | G60: 가격 접근
A61: 칸데릴라왁스 | B61: 5 | C61: 2 | D61: 4 | E61: 4 | F61: 5 | G61: 3
A62: 밀랍(비즈왁스) | B62: 3 | C62: 4 | D62: 2 | E62: 3 | F62: 1 | G62: 4
A63: 코코아버터 | B63: 3 | C63: 1 | D63: 2 | E63: 2 | F63: 5 | G63: 3
A64: 시어버터 | B64: 2 | C64: 2 | D64: 1 | E64: 1 | F64: 5 | G64: 4
A65: 세틸알코올 | B65: 3 | C65: 1 | D65: 1 | E65: 2 | F65: 5 | G65: 5
A66: 식물성 바세린(에코바세린) | B66: 2 | C66: 5 | D66: 3 | E66: 2 | F66: 5 | G66: 3
...

Sheet 제형 설계
A1: 제형 설계 — 원하는 제형을 만들려면 무엇을 얼마나
A2: %는 연습용 출발점. '핵심 원료'는 보유 원료 위주로 적었고 숫자=대략 %. 감촉 레버로 미세조정 → 개발일지에 기록. 기능성(자외선·미백·주름) 표방은 보고 필요 → OEM 영역.
A4: 제형 | B4: 목표 감촉 | C4: 점도 | D4: 구조(뼈대) | E4: 수상% | F4: 유상% | G4: 핵심 원료(보유 위주, ≈%) | H4: 추가하면 좋은 원료 | I4: 감촉 레버 | J4: 흔한 실패 → 원인 | K4: 공정 포인트 | L4: 지금 보유로?
A5: 토너(스킨) | B5: 물처럼 산뜻, 바르면 촉촉 | C5: 물~약간 점성 | D5: 수상 단독(+가용화) | E5: 90~97% | F5: 0~1% | G5: 정제수·글리세린 2·프로판디올 3·베타인·판테놀 1·알란토인 0.2·페녹시+헥산디올 | H5: 폴리글리세릴-4 카프레이트(향 넣을 때) | I5: 보습제 합 5→10%=촉촉↑끈적↑ / 히알루론산 0.02%=미끌 | J5: 뿌옇다→향 가용화 부족 / 끈적→글리세린 과다 | K5: 가열 불필요, 분말은 먼저 완전 용해 | L5: ✓ 가능
A6: 수분 젤(잔탄) | B6: 말랑, 천연 느낌 | C6: 중간 | D6: 점증제 젤(잔탄±HEC) | E6: 95~98% | F6: 0~2% | G6: 정제수·잔탄 0.3~0.5(글리세린 선분산)·글리세린·판테놀·마데카소사이드·방부 | H6: HEC(실끈↓) | I6: 잔탄↑=쫀득·실끈 / 글리세린↓=덜 끈적 | J6: 덩어리(피쉬아이)→선분산 안 함 / 콧물감→잔탄 과다 | K6: 글리세린에 잔탄 개어 물에 투입, 고속 교반, 하룻밤 숙성 | L6: ✓ 가능
A7: 물광 젤(카보머) | B7: 투명·탱글·산뜻 | C7: 중~높음 | D7: 중화형 젤 | E7: 95~98% | F7: 0% | G7: 정제수·카보머 0.3·트로메타민(중화)·글리세린 3·프로판디올 2·판테놀·방부 | H7: — | I7: 카보머 0.2→0.5=점도↑ / 중화 pH 6~7 최적 | J7: 점도 안 오름→전해질(아연피카·염) / pH 너무 높음 | K7: 카보머 분산→수화 30분→다른 원료→마지막 중화 | L7: 주문 입고 후 가능
A8: 젤크림 | B8: 젤처럼 가볍게 크림처럼 촉촉 | C8: 중간 | D8: 젤 + 소량 유상(유화제 少 or 세피노브) | E8: 80~90% | F8: 5~12% | G8: 젤 베이스 + MCT 5·스쿠알란 3 + 몬타노브 1.5~2(저농도 유화) | H8: 세피노브 EMT10(유화제 없이) | I8: 오일↑=촉촉·무게↑ / 디메치콘 1%=보송 | J8: 분리→유화제 부족 / 기름짐→오일 과다 | K8: B상 80℃ 녹여 A상(젤)에 투입, 호모믹서 | L8: ✓ 가능(몬타노브 저농도)
A9: 세럼·에센스 | B9: 가볍고 미끄러운 점성 액 | C9: 낮~중간 | D9: 약한 점증 + 활성 고함량 | E9: 85~95% | F9: 0~3% | G9: 정제수·잔탄 0.15·HA 0.1·나이아신 4·아연피카 0.5·판테놀·베타글루칸·방부 | H9: — | I9: HA·베타글루칸=미끈·막 / 잔탄 0.1~0.2만 | J9: 따끔→나이아신 고% / 밀림→HA 과다 | K9: 활성은 냉각상 or 미리 녹인 수용액 | L9: ✓ 가능
A10: 로션(에멀전) | B10: 묽고 빨리 스며듦 | C10: 흐름 | D10: O/W 유화(유화제 2~3%) | E10: 75~85% | F10: 8~15% | G10: A: 정제수·글리세린·잔탄 0.1 / B: MCT·스쿠알란·올리브유화왁스 3 / C: 판테놀·방부 | H10: Tego Care 450 | I10: 유화제·세틸↓=묽게 / 디메치콘=가벼운 슬립 | J10: 분리→유화제 대비 오일 과다 / 묽어짐→냉각 교반 부족 | K10: A·B 둘 다 75℃ → B를 A에 넣고 유화 → 40℃까지 저으며 냉각 | L10: ✓ 가능
A11: 크림(히어로형) | B11: 쫀쫀·보들, 장벽 느낌 | C11: 높음 | D11: O/W 액정 유화(몬타노브) | E11: 70~80% | F11: 15~22% | G11: A: 정제수·글리세린·프로판디올·나이아신·알란토인·잔탄 0.3 / B: 몬타노브 4·세틸 2·MCT 3·스쿠알란 5·디메치콘 3 / C: 판테놀·마데카·녹차·페녹시·헥산디올 | H11: 세라마이드(리포좀) | I11: 세틸 0.5% 단위=점도 / 디메치콘=소핑↓ / 스쿠알란↔MCT=흡수감 | J11: 하얘짐→소핑(디메치콘↑) / 알갱이→고온 부족 / 묽음→24h 후 판단 | K11: B 80℃ 완전 용해, 유화 후 냉각 교반, 점도는 24~48h 뒤 확정 | L11: ✓ 현재 v2 처방
A12: 리치 크림·나이트 | B12: 꾸덕·보호막 | C12: 매우 높음 | D12: O/W 고유상 | E12: 55~70% | F12: 25~40% | G12: 몬타노브 5·세틸 3·시어버터 5~10·스쿠알란·호호바·토코페롤 0.3 | H12: 콜레스테롤·세라마이드 | I12: 버터↑=리치 / 디메치콘=무게 감춤 | J12: 그레이니→시어 서냉 / 분리→유화제 부족 | K12: 버터 저온 용해 후 빠르게 유화·냉각 | L12: ✓ 가능(시어·호호바, 히어로 X)
A13: 밤(무수) | B13: 체온에 녹는 고체 | C13: 고체 | D13: 오일 + 왁스/버터 (물 없음) | E13: 0% | F13: 100% | G13: 시어버터 30·MCT/호호바 50·칸데릴라 10·토코페롤 0.5 | H13: 타피오카전분(기름짐↓) | I13: 왁스↑=단단 / 버터↑=녹는감 / 액상오일↑=부드러움 | J13: 그레이니→급냉 안 함 / 너무 단단→왁스 과다 | K13: 무수라 방부제 불필요(물 닿지 않게), 70℃ 녹여 용기 붓고 급냉 | L13: 칸데릴라 구매 시 가능
A14: 오일 세럼(무수) | B14: 가벼운 페이스 오일 | C14: 흐름 | D14: 오일 블렌드 | E14: 0% | F14: 100% | G14: 스쿠알란 50·MCT 40·호호바 9·토코페롤 0.5 | H14: 코코카프릴레이트(가볍게) | I14: 에스터↑=가볍게 / 버터↑=무겁게 | J14: 산패 냄새→토코페롤 누락·불포화 오일 과다 | K14: 가열 불필요, 차광병 | L14: ✓ 가능
A15: 물리 선크림 | B15: 백탁 최소, 매트 | C15: 중간 | D15: W/O or O/W + 무기 분말 | E15: 40~60% | F15: 25~40% | G15: 징크옥사이드 15~25·C12-15·디카프릴릴카보네이트·포타슘세틸포스페이트 | H15: — | I15: 분산 품질=차단·백탁 결정 | J15: 뭉침·백탁→분산 부족 | K15: ★ 자외선차단 = 기능성 보고·SPF 시험 → OEM 영역 | L15: ✗ (OEM 의뢰)
... A25: 배스밤 | B25: 물에 넣으면 거품·발포 | C25: 고체 | D25: 산-염기 발포 + 계면 | E25: 0% | F25: ~5% | G25: 베이킹소다 50·구연산 25·옥수수전분 10·SLSA 5~10·오일 3~5·위치하젤 분사(성형) | H25: — | I25: 구연산 비율=발포 세기 / SLSA=거품 | J25: 미리 부풂→습기 / 부서짐→결합 수분 부족 | K25: 습도 낮은 날, 분사하며 성형 | L25: 구매 필요

Sheet 감촉 레버
A1: 감촉 레버 — 원하는 느낌으로 옮기는 손잡이
A2: 만든 제형이 마음에 안 들 때: 원하는 변화 행을 찾아 '올리기/내리기/바꾸기' 중 하나만 바꿔 다시 만든다(한 번에 한 변수).
A4: 원하는 변화 | B4: 올리기(+) | C4: 내리기(−) | D4: 바꾸기(A→B) | E4: 원리 | F4: 확인 실험
A5: 더 산뜻하게(덜 끈적) | B5: 프로판디올·베타인 비중 | C5: 글리세린·판테놀%·HA% | D5: 글리세린 일부→베타인 | E5: 다가알코올 중 글리세린이 가장 끈적 | F5: 글리세린 5% vs 글리세린2+베타인3
A6: 더 촉촉하게 | B6: 글리세린·HA·베타글루칸 | C6: — | D6: — | E6: 휴멕턴트 + 막 형성 고분자 | F6: HA 0.05→0.15
A7: 더 쫀쫀(바디감) | B7: 몬타노브·세틸알코올 | C7: 물 | D7: 올리벰→몬타노브 | E7: 액정 + 지방알코올 망상 구조 | F7: 세틸 1 vs 2 vs 3
A8: 더 묽게(로션화) | B8: 물 | C8: 세틸알코올·유화제·잔탄 | D8: 몬타노브→Tego Care | E8: 지방알코올이 점도 대부분을 만든다 | F8: 세틸 0 vs 1
A9: 바를 때 하얘짐(소핑) 없애기 | B9: 디메치콘 1~2%·에스터 | C9: 세틸·스테아릴 알코올 | D9: — | E9: 지방알코올 결정이 문지를 때 거품처럼 보임 | F9: 디메치콘 0 vs 2
A10: 흡수 빠르게 | B10: 스쿠알란·코코카프릴레이트 | C10: 시어·호호바 | D10: MCT→스쿠알란 | E10: 저점도·분지/포화 오일 = 빠른 퍼짐 | F10: 오일 한 방울 퍼짐 면적
A11: 기름짐·번들거림 줄이기 | B11: 실리카·전분 0.5~2% | C11: 총 유상% | D11: 무거운 오일→에스터 | E11: 분말이 표면 유분 흡착 | F11: 타피오카 0 vs 2
A12: 보호막·리치하게 | B12: 시어버터·미네랄오일 | C12: 에스터 | D12: MCT→시어 | E12: 차폐성(수분 증발 차단) | F12: 물방울 튕김 테스트
A13: 투명 젤로 | B13: 카보머 | C13: 잔탄 | D13: 잔탄→카보머/HEC | E13: 잔탄은 본질적으로 탁함 | F13: 잔탄 vs 카보머 글자 비쳐 보기
A14: 실끈(콧물감) 없애기 | B14: HEC·스클레로튬 | C14: 잔탄 | D14: 잔탄 일부→HEC | E14: 잔탄 긴 사슬이 늘어남 | F14: 잔탄 0.5 vs 잔탄0.25+HEC0.25
A15: 미끄러운 슬립 | B15: 디메치콘·코코카프릴레이트 | C15: 점증제% | D15: — | E15: 저표면장력 막 | F15: 디메치콘 2%
... A32: 클렌징 오일 잘 씻기게 | B32: 유화형 계면(올리브리퀴드 등) | C32: 무거운 오일 | D32: 식물유→세틸에틸헥사노에이트 | E32: 물 닿을 때 O/W 유화 | F32: 손에 물 묻혀 유화 테스트

Sheet 블렌드 해부
A1: 블렌드 해부 — 상품명·블렌드 원료 26종을 단일 원료로 쪼개 읽기
A2: 허브누리 레시피에 자주 나오지만 성분이 공개되지 않은 원료. 카드를 지어내지 않고 '무엇으로 만들었을까 → 내 카드 어디와 연결되나 → 직접 만들면 → 살 때 무엇을 받아야 하나'로 정리. 추정 주성분은 판매처 설명 기반 (예) — 공급사 전성분/TDS로 확정. OEM·판매처에 물어볼 질문 목록으로 그대로 쓰기. 상태 칸은 자유 입력(재생성해도 보존).
A4: 원료(도감) | B4: 등장수 | C4: 판매처 설명(도감) | D4: 추정 주성분(예) | E4: 연결 카드 | F4: 직접 만들면(≈%) | G4: 살 때 받을 자료·질문 | H4: 광고 표현 주의 | I4: 상태
A5: 로즈플라워겔 | B5: 36 | C5: 불가리아 다마스크 장미수가 함유된 젤상 수상 원료. 즉각적인 수분 공급 및 수렴·진정. | D5: (예) 다마스크 로즈워터 + 점증제(카보머/잔탄) + 알란토인 + 보존 성분 | E5: 로즈워터(하이드로졸) · 카보머 · 알란토인 | F5: 로즈워터 97 + 카보머 0.3(중화) + 알란토인 0.1 + 방부 | G5: 전성분 순서, 점증제 종류(전해질 넣을 때 깨지는지), 방부 성분 | H5: '수렴·진정'은 무난, '염증 완화'는 금지
A6: 로즈플라워 아로마수 | B6: 3 | C6: 아로마 오일 가용화 및 자생적 보존력을 높인 수용성 보존 처방 베이스(로즈플라워 향). | D6: (예) 정제수/로즈워터 + 가용화제(폴리소르베이트20 등) + 향료/EO + 보존 성분 | E6: 로즈워터(하이드로졸) · 폴리소르베이트20 · 로즈제라늄에센셜오일 | F6: 정제수 95 + (EO 0.2 : 폴리소르베이트20 0.8 선혼합) + 방부 | G6: 가용화제 종류·%, 향이 EO인지 합성 향료인지, 알레르기 성분 | H6: '자생적 보존력' = 방부 대체 아님 → 방부 시스템 별도 확인
A7: 오렌지꽃 아로마수 | B7: 3 | C7: 네롤리와 일랑일랑 에센셜 오일이 수용화되어 깔끔하게 섞이는 아로마 워터 처방. | D7: (예) 정제수 + 가용화제 + 네롤리·일랑일랑 EO + 보존 성분 | E7: 네롤리워터 · 네롤리에센셜오일 · 일랑일랑에센셜오일 · 폴리소르베이트20 | F7: 네롤리워터 95 + (네롤리·일랑 EO 0.2 : 가용화제 0.8) + 방부 | G7: EO 함량, 가용화제, 알레르기 성분(리날룰 등) | H7: —
A8: 어린 콜라겐겔 | B8: 8 | C8: 저분자 마린 콜라겐, 나이아신아마이드, 로즈워터 배합 젤. 수분 탄력 및 미백 케어. | D8: (예) 저분자 마린콜라겐 + 나이아신아마이드 + 로즈워터 + 점증제 | E8: 가수분해콜라겐(마린·식물 콜라겐) · 나이아신아마이드 · 로즈워터(하이드로졸) · 카보머 | F8: 로즈워터 base + 가수분해콜라겐 3 + 나이아신아마이드 2~5 + 카보머 0.3 | G8: 나이아신아마이드 함량(2%↑면 미백 기능성 원료 함량), 콜라겐 분자량·유래 | H8: 미백 표방은 기능성 보고 제품만 → OEM 영역
A9: 알로에모이스트 | B9: 8 | C9: 알로에베라 기반 농축 습윤 성분. 피부 수분 충전, 열감 완화 및 점도 형성. | D9: (예) 알로에베라잎즙/추출물 + 보습제(글리세린·BG) + 점증제 | E9: 알로에베라겔 · 글리세린 · 잔탄검 | F9: 알로에베라겔 + 글리세린 3 + 잔탄 0.2 | G9: 알로에 실함량(%), 원물/분말 환원 여부 | H9: '열감 완화'는 무난, '화상 치료'는 금지
A10: 라벤더오일 | B10: 9 | C10: 라벤더 추출 유상 보습 성분. 자극 완화, 피부 진정 및 편안한 아로마 효과 제공. | D10: 정체 확인 필요 — EO가 아니라 '유상 보습' 설명 → 라벤더 인퓨즈오일(베이스 오일+라벤더) 추정 | E10: 라벤더에센셜오일 · 카렌듈라 인퓨즈드오일 · 호호바오일 | F10: 호호바오일 99.5 + 라벤더 EO 0.5 (향) / 또는 라벤더 꽃 인퓨즈 | G10: ★ EO인지 인퓨즈오일인지(사용 %가 완전히 다름), 베이스 오일 종류 | H10: —
A11: 올리브에스터오일 | B11: 5 | C11: 올리브 오일 유래 실리콘 대용 에스테르 오일. 실리콘처럼 가벼우면서도 긴 보습 유지력을 제공. | D11: (예) 올리브 지방산 에스터(Ethylhexyl Olivate / Decyl Olivate 등) | E11: 코코-카프릴레이트/카프레이트 · 디카프릴릴카보네이트 · 세틸에틸헥사노에이트 | F11: 코코-카프릴레이트 or 세틸에틸헥사노에이트로 대체 비교 | G11: INCI(에스터 종류), 점도·퍼짐 수치 | H11: '실리콘 대체'는 감촉 표현일 뿐 — '실리콘 프리' 표기는 전성분 확인 후
A12: 올리브상온유화제 | B12: 9 | C12: 가열 과정 없이 상온에서 물과 오일을 믹싱하여 에멀전을 형성하는 비이온성 유화제. 열에 약한 유효성분 보호에 적합함. | D12: (예) 올리브유 유래 에스터 유화제(Olive Oil PEG-7 Esters 또는 폴리글리세릴 에스터 계열) | E12: 세피노브 EMT10 · 폴리글리세릴-4 카프레이트 · 올리브유화왁스(올리벰1000) | F12: 냉간 젤크림이 목적이면 세피노브 EMT10 1% + 오일 10 | G12: INCI, PEG 포함 여부(천연 포지션), 오일 최대 몇 %까지 잡는지 | H12: '무가열'은 공정 표현 — 효능 아님
A13: 올리브 소프트왁스 | B13: 3 | C13: 올리브 오일 유래 유화 보조 및 경화제. 끈적임 없는 가벼운 밤(Balm) 및 질감의 크림을 완성함. | D13: (예) 올리브 유래 왁스 에스터(수소첨가 올리브오일 계열) | E13: 시어버터 · 코코아버터 · 세틸알코올 · 칸데릴라왁스 | F13: 밤: 시어 15 + 세틸알코올 3 (덜 끈적·부드러운 경도) | G13: INCI, 녹는점(℃), 단독 경화력 | H13: —
A14: 멀티밤왁스 | B14: 8 | C14: 밀랍과 칸데릴라왁스를 최적 비율로 혼합하여 부드러운 발림성과 스틱 제형의 형태 유지력을 동시에 제공하는 왁스 베이스. | D14: 밀랍 + 칸데릴라왁스 혼합(판매처 설명) | E14: 밀랍(비즈왁스) · 칸데릴라왁스 | F14: 밀랍 : 칸데릴라 = 2:1부터 → 경도 보고 조정 | G14: 혼합 비율, 녹는점 | H14: 비건 표기 불가(밀랍 포함)
A15: 화이트펩타이드 | B15: 12 | C15: 비타민 유도체 결합 펩타이드. 멜라닌 생성 억제 및 피부 톤업·미백 시너지. | D15: (예) 비타민 유도체 + 펩타이드(노나펩타이드-1 등) + 용매 | E15: 나이아신아마이드 · 아스코빌글루코사이드 · 매트릭실 3000 (팔미토일 펩타이드) | F15: 톤 케어 목적이면 고시 성분 단일(나이아신아마이드 2~5)이 명확 | G15: 펩타이드 INCI·ppm, 비타민 유도체 종류·함량 | H15: ★ '멜라닌 억제·미백'은 기능성 보고 제품만
A16: 아카시아콜라겐 | B16: 11 | C16: 아카시아나무 유래 식물성 콜라겐. 수분 보유력 향상 및 매끈한 수분 탄력막 형성. | D16: (예) 아카시아(세네갈)검 + 글리세린 등 — 실제 콜라겐(단백질) 아님 | E16: 가수분해콜라겐(마린·식물 콜라겐) · 폴리글루타믹애씨드(PGA) · 잔탄검 | F16: PGA 0.5 + 잔탄 0.1 → 매끈한 수분막 감촉 재현 | G16: INCI(검 종류), '콜라겐'이 들어간 이유(감촉 이름) | H16: ★ '식물성 콜라겐' = 오인 표현 위험 → 성분명대로
... A30: 브라이트닝 에센셜오일 | B30: 3 | C30: 네롤리, 일랑일랑, 버가못FCF · 프랑킨센스 EO 블렌딩오일 | D30: 네롤리 + 일랑일랑 + 버가못FCF + 프랑킨센스 EO 블렌드(판매처 설명) | E30: 네롤리에센셜오일 · 일랑일랑에센셜오일 · 버가못FCF 에센셜오일 · 프랑킨센스에센셜오일 | F30: 버가못FCF 3 : 네롤리 1 : 일랑 1 : 프랑킨센스 2부터 시향 조정 | G30: 블렌드 비율, 알레르기 성분 | H30: ★ '브라이트닝' 이름이 미백 오인 → 제품 광고엔 쓰지 말 것

Sheet 다음 공부
A1: 다음 공부 대기열 — 원료 도감에서 아직 카드가 없는 원료
A2: 제품개발_마스터 '원료 도감'에서 자동 추출: 기능성 전체 + 허브누리 등장 2회↑ 단일 원료. 블렌드·상품명 원료는 '블렌드 해부' 시트로, 완제 베이스·방향제는 제외. 이름 표기 차이로 이미 카드가 있는 원료가 섞일 수 있음 — '후보' 목록. 관심 원료는 스크립트 카드 파일에 한 줄 추가 → 재생성. 상태 칸은 자유 입력(재생성해도 보존).
A4: 구분 | B4: 역할 | C4: 원료(도감) | D4: 등장수 | E4: 전형/사용% | F4: 기능·특징(도감) | G4: 상태
A5: 허브누리 | B5: 수상 | C5: 식물성 에탄올 70% | D5: 2 | E5: 89 ~ 94 ~ 99% | F5: 곡물 발효 유래 에탄올 70%. 가용화 보조, 살균 소독 및 제형 청량감 부여.
A6: 허브누리 | B6: 수상 | C6: 자작나무수액 | D6: 2 | E6: 24 ~ 25 ~ 26% | F6: 자작나무 유래 천연 미네랄 수액. 피부 보습인자와 유사하여 우수한 피부 침투 및 보습.
A7: 허브누리 | B7: 유상 | C7: 참깨오일 | D7: 2 | E7: 16 ~ 18 ~ 21% | F7: 생참깨 압착 오일. 자연 항산화 성분(세사몰)과 올레산이 풍부하여 피부 영양 및 진정.
A8: 허브누리 | B8: 유상 | C8: 푸에라리아오일 | D8: 2 | E8: 11 ~ 11 ~ 11% | F8: 푸에라리아 뿌리 성분을 우려낸 인퓨즈드 오일. 피부 탄력 케어 지원.
A9: 허브누리 | B9: 유상 | C9: 모링가오일 | D9: 2 | E9: 10 ~ 10 ~ 10% | F9: 모링가 씨앗 압착 오일. 풍부한 아미노산과 비타민 성분으로 항산화, 피부 정화 및 장벽 보호.
A10: 허브누리 | B10: 유상 | C10: 유기농 세티올 에스터오일 | D10: 2 | E10: 7 ~ 8 ~ 9% | F10: 코코넛 유래 유기농 에스테르 오일. 가볍고 발림성이 뛰어나 제형의 답답함을 줄여줌.
A11: 허브누리 | B11: 유상 | C11: 식물성 스쿠알렌 | D11: 2 | E11: 5 ~ 5 ~ 6% | F11: 올리브 오일 유래 식물성 스쿠알렌. 피부 지질 친화성이 우수하여 친화적 보습 및 활력 부여.
A12: 허브누리 | B12: 경화 | C12: 에코소이왁스 | D12: 2 | E12: 83 ~ 87 ~ 92% | F12: 100% 콩기름 유래 천연 왁스. 융점이 낮아 마사지 캔들 및 바디 밤 제작에 사용됨.
A13: 허브누리 | B13: 경화 | C13: 라놀린 | D13: 2 | F13: 양모 유래 천연 지용성 왁스. 피부 지질 구조와 매우 유사하여 극건성 부위 수분 보호막 형성 및 입술 보호 효과 탁월.
A14: 허브누리 | B14: 계면 | C14: 구아클로라이드 | D14: 2 | E14: 0 ~ 1 ~ 1% | F14: 양이온성 점증 및 컨디셔닝제. 모발 정전기 방지 및 부드러운 유연 효과.
A15: 허브누리 | B15: 활성 | C15: 클로렐라추출물 | D15: 2 | E15: 5 ~ 7 ~ 10% | F15: 담수 단백질 해조류 클로렐라 추출물. 미네랄과 비타민 공급, 피부 활력.
A16: 허브누리 | B16: 활성 | C16: 하수오추출물 | D16: 2 | E16: 12 ~ 12 ~ 12% | F16: 적하수오 뿌리 추출물. 두피 영양 공급 및 모발 건강 유지.
A17: 허브누리 | B17: 활성 | C17: 푸에라리아추출물 | D17: 2 | E17: 15 ~ 15 ~ 15% | F17: 식물성 에스트로겐이 풍부한 푸에라리아 뿌리 추출물. 피부 탄력 강화 지원.
A18: 허브누리 | B18: 활성 | C18: 비피다발효여과물 | D18: 2 | E18: 20 ~ 32 ~ 45% | F18: 비피더스균 발효 용해물. 피부 장벽 강화, 면역력 유도 및 매끈한 결 케어.
A19: 허브누리 | B19: 활성 | C19: 라벤더추출물 | D19: 2 | E19: 8 ~ 8 ~ 8% | F19: 라벤더 꽃 수용성 추출물. 자극 완화 및 트러블 진정.
A20: 허브누리 | B20: 활성 | C20: 진주가루 | D20: 2 | E20: 1 ~ 1 ~ 1% | F20: 미네랄과 아미노산이 풍부한 진주 분말. 매끈한 피부 결 및 화사한 톤 연출.
A21: 허브누리 | B21: 활성 | C21: 현미유 | D21: 2 | E21: 10 ~ 13 ~ 15% | F21: 쌀겨 압착 오일. 감마오리자놀과 비타민 E가 풍부해 가볍고 순한 보습.
A22: 허브누리 | B22: 활성 | C22: PCG | D22: 2 | E22: 21 ~ 21 ~ 21% | F22: 글리신 유래 아미노산계 습윤제. 저자극 보습 및 피부 장벽 케어.
A23: 허브누리 | B23: 활성 | C23: 진주분말 | D23: 2 | E23: 16 ~ 16 ~ 16% | F23: 진주 펄 미네랄 파우더. 피부 톤 맑음 케어 및 투명한 결 개선.
A24: 허브누리 | B24: 활성 | C24: 녹는 실 콜라겐 | D24: 2 | E24: 4 ~ 4 ~ 4% | F24: 저분자 콜라겐과 히알루론산 실. 체온에 녹아 피부에 탄력 수분 침투.
A25: 허브누리 | B25: 활성 | C25: 바이오 디톡스 | D25: 2 | E25: 5 ~ 7 ~ 10% | F25: 해독 효소 활성화 및 모공 노폐물 정화를 돕는 항산화 바이오 복합체.
... A34: 허브누리 | B34: 향 | C34: 팔마로사 에센셜오일 | D34: 2 | E34: 0 ~ 0 ~ 0% | F34: 팔마로사 풀 증기 추출 오일. 장미와 유사한 향, 유수분 균형 조절 및 보습.
A35: 허브누리 | B35: 향 | C35: 그레이프프룻EO | D35: 2 | F35: 자몽 껍질 압착 오일. 상쾌한 시트러스 향, 모공 수렴 및 슬리밍 케어 아로마.
A36: 허브누리 | B36: 색소 | C36: 컬러믹스 파운데이션 | D36: 2 | E36: 13 ~ 13 ~ 13% | F36: 티타늄디옥사이드 기반 색소 복합체. 파운데이션 및 BB크림용 커버 파우더.
A37: 허브누리 | B37: 방부 | C37: 나트로틱스 | D37: 2 | E37: 2 ~ 2 ~ 2% | F37: 초피나무, 할미꽃, 어성초 등 천연 복합 추출물. 광범위한 항균 스펙트럼과 강력한 산화 방지, 피부 진정 효과 제공.
A38: 허브누리 | B38: 방부 | C38: 수용성 보존제 | D38: 2 | E38: 1 ~ 1 ~ 1% | F38: 복합 식물 추출물 베이스로 스킨, 에센스 등 수성 제형에 용해되는 미생물 억제제.
A39: 허브누리 | B39: 점증/pH | C39: 글루카메이트 | D39: 2 | E39: 3 ~ 3 ~ 4% | F39: 옥수수 유래 비이온성 점증제. 샴푸/바디워시 자극을 낮추고 쫀쫀한 점도를 형성함 (가열 용해 필요).
A40: 허브누리 | B40: 분말·스크럽 | C40: 어성초분말 | D40: 2 | E40: 13 ~ 13 ~ 13% | F40: 어성초(약모밀) 건조 분말. 쿠에르치트린 성분 함유로 강력한 항균, 여드름 및 트러블 완화.
A41: 허브누리 | B41: 분말·스크럽 | C41: (유기농) 설탕 | D41: 2 | E41: 47 ~ 51 ~ 56% | F41: 천연 습윤 작용을 하는 글루코스 입자. 물리적 자극 없이 피지·각질을 녹여내는 립/바디 스크럽 성분.
